Workbook

Sheet 1º
A1: PARTE DE 1º AÑO - 2026 - | H1: 46293
A2: LUNES | D2: =H1 -> 46293 | H2: 46294
A3: ASIGNATURA | B3: FIRMA PROFESOR | C3: ALUMNOS AUSENTE | D3: INASISTENCIA JUSTIFICADA | E3: OBSERVACIONES | H3: 46295
H4: =H3+1 -> 46296
A5: FORM. ETICA Y CIUD. | H5: =H4+1 -> 46297
A6: FORM. ETICA Y CIUD.
A7: MATEMATICA
A8: MATEMATICA
A9: LENGUA
A10: LENGUA
A11: MUSICA
A12: MUSICA
A13: FÍSICA Y QUÍMICA
A14: FÍSICA Y QUÍMICA
A15: MARTES | D15: =H2 -> 46294
A16: ASIGNATURA | B16: FIRMA PROFESOR | C16: ALUMNOS AUSENTE | D16: INASISTENCIA JUSTIFICADA | E16: OBSERVACIONES
A18: INGLÉS
A19: INGLÉS
A20: MATEMATICA
A21: MATEMATICA
A22: LENGUA
A23: LENGUA
A24: ITALIANO
A25: ITALIANO
A26: ED FISICA
A27: ED FISICA
A28: MIÈRCOLES | D28: =H3 -> 46295
A29: ASIGNATURA | B29: FIRMA PROFESOR | C29: ALUMNOS AUSENTE | D29: INASISTENCIA JUSTIFICADA | E29: OBSERVACIONES
A31: FISICO-QUIMICA
A32: HISTORIA
A33: TUTORIA
A34: TUTORIA
A35: GEOGRAFIA
A36: GEOGRAFIA
A37: ARTES VISUALES
A38: ARTES VISUALES
A39: INGLES
A40: BIOLOGÍA
A41: JUEVES | D41: =H4 -> 46296
A42: ASIGNATURA | B42: FIRMA PROFESOR | C42: ALUMNOS AUSENTE | D42: INASISTENCIA JUSTIFICADA | E42: OBSERVACIONES
...

Sheet 2º
A1: PARTE DE 2º AÑO - 2026 -
A2: LUNES | D2: ='1º'!H1 -> 46293
A3: ASIGNATURA | B3: FIRMA PROFESOR | C3: ALUMNOS AUSENTE | D3: INASISTENCIA JUSTIFICADA | E3: OBSERVACIONES
A5: FISICO-QUIMICA
A6: FISICO-QUIMICA
A7: FORMACION ET Y CIUD
A8: FORMACION ET Y CIUD
A9: ED. TECN (INFORM)
A10: ED. TECN (INFORM)
A11: LENGUA
A12: LENGUA
A13: MUSICA
A14: MUSICA
A15: MARTES | D15: ='1º'!H2 -> 46294
A16: ASIGNATURA | B16: FIRMA PROFESOR | C16: ALUMNOS AUSENTE | D16: INASISTENCIA JUSTIFICADA | E16: OBSERVACIONES
A18: ITALIANO
A19: ITALIANO
A20: INGLES
A21: INGLES
A22: MATEMATICA
A23: MATEMATICA
A24: LENGUA
A25: LENGUA
A26: MIERCOLES | D26: ='1º'!H3 -> 46295
A27: ASIGNATURA | B27: FIRMA PROFESOR | C27: ALUMNOS AUSENTE | D27: INASISTENCIA JUSTIFICADA | E27: OBSERVACIONES
A29: TUTORIA
A30: TUTORIA
A31: GEOGRAFIA
A32: GEOGRAFIA
A33: HISTORIA
A34: HISTORIA
A35: INGLES
A36: BIOLOGIA
A37: ARTES VISUALES
A38: ARTES VISUALES
A39: JUEVES | D39: ='1º'!H4 -> 46296
A40: ASIGNATURA | B40: FIRMA PROFESOR | C40: ALUMNOS AUSENTE | D40: INASISTENCIA JUSTIFICADA | E40: OBSERVACIONES
A42: MATEMATICA
A43: MATEMATICA
A44: TUTORIA DISCIPLINAR (LENGUA)
...

Sheet 3º
A1: PARTE DE 3º AÑO - 2026 -
A2: LUNES | D2: ='1º'!H1 -> 46293
A3: ASIGNATURA | B3: FIRMA PROFESOR | C3: ALUMNOS AUSENTE | D3: INASISTENCIA JUSTIFICADA | E3: OBSERVACIONES
A5: MATEMATICA
A6: MATEMATICA
A7: LENGUA
A8: LENGUA
A9: ARTES VISUALES
A10: ARTES VISUALES
A11: FISICO-QUIMICA
A12: FISICO-QUIMICA
A13: ED. TECN (INFORM)
A14: ED. TECN (INFORM)
A15: MARTES | D15: ='1º'!H2 -> 46294
A16: ASIGNATURA | B16: FIRMA PROFESOR | C16: ALUMNOS AUSENTE | D16: INASISTENCIA JUSTIFICADA | E16: OBSERVACIONES
A18: MATEMATICA
A19: MATEMATICA
A20: TUTORIA (LENGUA)
A21: LENGUA
A22: INGLES
A23: INGLES
A24: ED. FÍSICA
A25: ED. FÍSICA
A26: MIERCOLES | D26: ='1º'!H3 -> 46295
A27: ASIGNATURA | B27: FIRMA PROFESOR | C27: ALUMNOS AUSENTE | D27: INASISTENCIA JUSTIFICADA | E27: OBSERVACIONES
A29: ITALIANO
A30: ITALIANO
A31: HISTORIA
A32: HISTORIA
A33: TUTORIA
A34: TUTORIA
A35: BIOLOGIA
A36: INGLES
A37: MUSICA
A38: MUSICA
A39: JUEVES | D39: ='1º'!H4 -> 46296
A40: ASIGNATURA | B40: FIRMA PROFESOR | C40: ALUMNOS AUSENTE | D40: INASISTENCIA JUSTIFICADA | E40: OBSERVACIONES
A42: ITALIANO
A43: ITALIANO
A44: MATEMATICA
...

Sheet 4º
A1: PARTE DE 4º AÑO - 2026 -
A2: LUNES | D2: ='1º'!H1 -> 46293
A3: ASIGNATURA | B3: FIRMA PROFESOR | C3: ALUMNOS AUSENTE | D3: INASISTENCIA JUSTIFICADA | E3: OBSERVACIONES
A5: FISICA
A6: FISICA
A7: ARTES VISUALES
A8: ARTES VISUALES
A9: LENGUA
A10: LENGUA
A11: HISTORIA
A12: HISTORIA
A13: INGLES
A14: INGLES
A15: MARTES | D15: ='1º'!H2 -> 46294
A16: ASIGNATURA | B16: FIRMA PROFESOR | C16: ALUMNOS AUSENTE | D16: INASISTENCIA JUSTIFICADA | E16: OBSERVACIONES
A18: LENGUA
A19: LENGUA
A20: ITALIANO
A21: ITALIANO
A22: PSICOLOGIA
A23: LENGUA
A24: ED. FÍSICA
A25: ED. FÍSICA
A26: MIERCOLES | D26: ='1º'!H3 -> 46295
A27: ASIGNATURA | B27: FIRMA PROFESOR | C27: ALUMNOS AUSENTE | D27: INASISTENCIA JUSTIFICADA | E27: OBSERVACIONES
A29: QUIMICA
A30: QUIMICA
A31: ITALIANO
A32: ITALIANO
A33: MATEMATICA
A34: MATEMATICA
A35: ECONOMIA
A36: ECONOMIA
A37: INGLES
A38: INGLES
A39: JUEVES | D39: ='1º'!H4 -> 46296
A40: ASIGNATURA | B40: FIRMA PROFESOR | C40: ALUMNOS AUSENTE | D40: INASISTENCIA JUSTIFICADA | E40: OBSERVACIONES
A42: FISICA
A43: FISICA
A44: BIOLOGIA
...

Sheet 5º
A1: PARTE DE 5º AÑO - 2026 -
A2: LUNES | D2: ='1º'!H1 -> 46293
A3: ASIGNATURA | B3: FIRMA PROFESOR | C3: ALUMNOS AUSENTE | D3: INASISTENCIA JUSTIFICADA | E3: OBSERVACIONES
A5: QUIMICA
A6: QUIMICA
A7: LITERATURA
A8: LITERATURA
A9: FISICA
A10: FISICA
A11: TIC´S
A12: TIC´S
A13: INGLES
A14: INGLES
A15: MARTES | D15: ='1º'!H2 -> 46294
A16: ASIGNATURA | B16: FIRMA PROFESOR | C16: ALUMNOS AUSENTE | D16: INASISTENCIA JUSTIFICADA | E16: OBSERVACIONES
A18: QUIMICA
A19: FILOSOFIA
A20: FILOSOFIA
A21: FILOSOFIA
A22: ITALIANO
A23: ITALIANO
A24: MATEMATICA
A25: MATEMATICA
A26: ED. FÍSICA
A27: ED. FÍSICA
A28: MIERCOLES | D28: ='1º'!H3 -> 46295
A29: ASIGNATURA | B29: FIRMA PROFESOR | C29: ALUMNOS AUSENTE | D29: INASISTENCIA JUSTIFICADA | E29: OBSERVACIONES
A31: HISTORIA
A32: CS. DE LA TIERRA
A33: MATEMATICA
A34: MATEMATICA
A35: LITERATURA
A36: LITERATURA
A37: GEOGRAFIA
A38: GEOGRAFIA
A39: INGLES
A40: INGLES
A41: JUEVES | D41: ='1º'!H4 -> 46296
A42: ASIGNATURA | B42: FIRMA PROFESOR | C42: ALUMNOS AUSENTE | D42: INASISTENCIA JUSTIFICADA | E42: OBSERVACIONES
A44: HISTORIA
...

Sheet 6º
A1: PARTE DE 6º AÑO - 2026 -
A2: LUNES | D2: ='1º'!H1 -> 46293
A3: ASIGNATURA | B3: FIRMA PROFESOR | C3: ALUMNOS AUSENTE | D3: INASISTENCIA JUSTIFICADA | E3: OBSERVACIONES
A5: LITERATURA
A6: LITERATURA
A7: FISICA
A8: FISICA
A9: HISTORIA
A10: HISTORIA
A11: ITALIANO
A12: ITALIANO
A13: INGLES
A14: INGLES
A15: MARTES | D15: ='1º'!H2 -> 46294
A16: ASIGNATURA | B16: FIRMA PROFESOR | C16: ALUMNOS AUSENTE | D16: INASISTENCIA JUSTIFICADA | E16: OBSERVACIONES
A18: ECOLOGIA
A19: ECOLOGIA
A20: IICSN
A21: IICSN
A22: MATEMATICA
A23: MATEMATICA
A24: QUIMICA
A25: QUIMICA
A26: ED. FÍSICA
A27: ED. FÍSICA
A28: MIERCOLES | D28: ='1º'!H3 -> 46295
A29: ASIGNATURA | B29: FIRMA PROFESOR | C29: ALUMNOS AUSENTE | D29: INASISTENCIA JUSTIFICADA | E29: OBSERVACIONES
A31: QUIMICA
A32: QUIMICA
A33: LITERATURA
A34: LITERATURA
A35: ITALIANO
A36: ITALIANO
A37: MATEMATICA
A38: MATEMATICA
A39: INGLES
A40: INGLES
A41: JUEVES | D41: ='1º'!H4 -> 46296
A42: ASIGNATURA | B42: FIRMA PROFESOR | C42: ALUMNOS AUSENTE | D42: INASISTENCIA JUSTIFICADA | E42: OBSERVACIONES
A44: ECOLOGIA
...

Sheet HS EXTRAS LUCHO
A1: MARZO
A2: DIA | C2: CANT DE HS
A3: LU | B3: 46090 | C3: 3
A4: MA | B4: 46091 | C4: 2
A5: MI | B5: 46092 | C5: 0
A6: JU | B6: 46093 | C6: 2
A7: VI | B7: 46094 | C7: 2
A8: LU | B8: 45732 | C8: 0 | H8: 19 | I8: 166000
A9: MA | B9: 45733 | C9: 0 | H9: 35
A10: MI | B10: 45734 | C10: 3
A11: JU | B11: 45735 | C11: 2
A12: VI | B12: 45736 | C12: 0 | H12: =(H9*I8)/H8 -> 305789.47
A13: LU | B13: 45739 | C13: 0
A14: MI | B14: 45741 | C14: 3
A15: JU | B15: 46107 | C15: 0
A16: VI | B16: 46108 | C16: 0
A17: LU | B17: 46111 | C17: 0
A18: MA | B18: 46112 | C18: 2
A19: TOTAL | C19: =SUM(C3:C18) -> 19
A22: ABRIL
A23: DIA | C23: CANT DE HS
A24: LU | B24: 46113 | C24: 3
A25: LU | B25: 45753 | C25: 0
A26: MA | B26: 45754 | C26: 0
A27: MI | B27: 45755 | C27: 3 | H27: 19 | I27: 166000
A28: JU | B28: 45756 | C28: 2 | H28: 40
A29: VI | B29: 45757 | C29: 2
A30: LU | B30: 46125 | C30: 3
A31: MA | B31: 46126 | C31: 2 | H31: =(H28*I27)/H27 -> 349473.68
A32: MI | B32: 46127 | C32: 0
A33: JU | B33: 46128 | C33: 2
A34: VI | B34: 46129 | C34: 2
A35: LU | B35: 45767 | C35: 3
A36: MA | B36: 45768 | C36: 2
A37: MI | B37: 45769 | C37: 0
A38: JU | B38: 45770 | C38: 2
A39: VI | B39: 45771 | C39: 2
A40: LU | B40: 45774 | C40: 3
A41: MA | B41: 45775 | C41: 2
A42: MI | B42: 45776 | C42: 0
...

Sheet ED FISICA
A1: MES MARZO | C1: MA | D1: JU | E1: VI | F1: MA | G1: JU | H1: VI | I1: MA | J1: JU | K1: VI | L1: MA | M1: JU | N1: JU | O1: VI
A2: CURSO | B2: PROFE | C2: 17 | D2: 19 | E2: 20 | F2: 24 | G2: 26 | H2: 27 | I2: 31
A3: 1° | B3: FRANCO/PECO | C3: pendiente parte fisico | D3: pendiente parte fisico | F3: Feriado | G3: pendiente parte fisico | I3: pendiente parte fisico
A4: 2° | B4: PECO/JUAN | D4: pendiente parte fisico | E4: pendiente parte fisico | G4: pendiente parte fisico | H4: pendiente parte fisico
A5: 3° | B5: PECO/YAMI | C5: pendiente parte fisico | D5: pendiente parte fisico | G5: pendiente parte fisico | I5: pendiente parte fisico
A6: 4º | B6: FRANCO/JUAN | C6: pendiente parte fisico | E6: pendiente parte fisico | H6: pendiente parte fisico | I6: pendiente parte fisico
A7: 5º | B7: PECO/JUAN | C7: pendiente parte fisico | D7: pendiente parte fisico | G7: pendiente parte fisico | I7: pendiente parte fisico
A8: 6º | B8: JUAN/YAMI | C8: pendiente parte fisico | E8: pendiente parte fisico | H8: pendiente parte fisico | I8: pendiente parte fisico
A10: MES ABRIL | C10: JU | D10: VI | E10: MA | F10: JU | G10: VI | H10: MA | I10: JU | J10: VI | K10: MA | L10: JU | M10: VI | N10: MA | O10: JU
A11: CURSO | B11: PROFE | C11: 2 | D11: 3 | E11: 7 | F11: 9 | G11: 10 | H11: 14 | I11: 16 | J11: 17 | K11: 21 | L11: 23 | M11: 24 | N11: 28 | O11: 30
A12: 1° | B12: FRANCO/PECO | C12: FERIADO | E12: sin informacion | F12: OK | H12: OK | I12: OK | K12: OK | L12: OK | N12: OK | O12: OK
A13: 2° | B13: PECO/JUAN | F13: OK | G13: OK | I13: OK | J13: SUSPENDIDO AUSENTE JUAN | L13: OK | M13: OK | O13: OK
A14: 3° | B14: PECO/YAMI | E14: OK | F14: OK | H14: OK | I14: OK | K14: OK | L14: OK | N14: OK | O14: OK
A15: 4º | B15: FRANCO/JUAN | E15: OK | G15: OK | H15: OK | J15: OK | K15: OK | M15: OK | N15: OK
A16: 5º | B16: PECO/JUAN | E16: OK | F16: OK | H16: SUSPENDIDO | I16: PENDIENTE CHIPPER | K16: OK | L16: OK | N16: OK | O16: OK
A17: 6º | B17: JUAN/YAMI | E17: OK | G17: OK | H17: OK | J17: OK | K17: OK | M17: OK | N17: OK
A19: MES MAYO | C19: MA | D19: JU | E19: VI | F19: MA | G19: JU | H19: VI | I19: MA | J19: JU | K19: VI | L19: MA | M19: JU | N19: VI
A20: CURSO | B20: PROFE | C20: 5 | D20: 7 | E20: 8 | F20: 12 | G20: 14 | H20: 15 | I20: 19 | J20: 21 | K20: 22 | L20: 26 | M20: 28 | N20: 29
A21: 1° | B21: FRANCO/PECO | C21: OK | D21: SUSPENDIDO | F21: PENDIENTE | G21: PENDIENTE | I21: OK | J21: PENDIENTE | L21: ok | M21: ok
A22: 2° | B22: PECO/JUAN | D22: SUSPENDIDO | E22: OK | G22: ok | H22: PENDIENTE | J22: PENDIENTE | K22: PENDIENTE | M22: ok | N22: ok
A23: 3° | B23: PECO/YAMI | C23: OK | D23: OK CHIPPER | F23: ok | G23: PENDIENTE | I23: PENDIENTE | J23: PENDIENTE | L23: ok | M23: ok
A24: 4º | B24: FRANCO/JUAN | C24: OK | E24: PENDIENTE | I24: ok | L24: ok
A25: 5º | B25: PECO/JUAN | C25: OK | D25: OK ESCUELA | F25: ok | L25: ok | M25: ok
A26: 6º | B26: JUAN/YAMI | C26: OK | E26: ok | L26: ok | N26: ok
A28: MES JUNIO | C28: MA | D28: JU | E28: VI | F28: MA | G28: JU | H28: VI | I28: MA | J28: JU | K28: VI | L28: MA | M28: JU | N28: VI | O28: MA
A29: CURSO | B29: PROFE | C29: 2 | D29: 4 | E29: 5 | F29: 9 | G29: 11 | H29: 12 | I29: 16 | J29: 18 | K29: 19 | L29: 23 | M29: 25 | N29: 26 | O29: 30
A30: 1° | B30: FRANCO/PECO | C30: ok | D30: ok | F30: OK | G30: 46260 | I30: ok | J30: ok | L30: CEF | M30: torneo atletismo | O30: 46260
A31: 2° | B31: PECO/JUAN | D31: ok | E31: PENDIENTE | G31: ok | H31: ok | J31: ok | K31: ok | M31: torneo atletismo | N31: PENDIENTE
A32: 3° | B32: PECO/YAMI | C32: ok | D32: ok | F32: ok | G32: ok | I32: ok | J32: ok | L32: CEF | M32: torneo atletismo | O32: ok
A33: 4º | B33: FRANCO/JUAN | C33: ok | E33: 46260 | F33: 46260 | H33: ok | I33: ok | K33: ok | L33: CEF | N33: 46260 | O33: 46260
A34: 5º | B34: PECO/JUAN | C34: ok | D34: ok | F34: ok | G34: ok | I34: ok | J34: ok | L34: SUSP. | M34: PENDIENTE | O34: ok
A35: 6º | B35: JUAN/YAMI | C35: ok | E35: PENDIENTE | F35: ok | H35: ok | I35: ok | K35: ok | L35: SUSP. | N35: ok | O35: ok
A37: MES JULIO | C37: JU | D37: VI | E37: MA | F37: JU | G37: VI | H37: MA | I37: JU | J37: VI
A38: CURSO | B38: PROFE | C38: 2 | D38: 3 | E38: 21 | F38: 23 | G38: 24 | H38: 28 | I38: 30 | J38: 31
A39: 1° | B39: FRANCO/PECO | C39: ok | E39: 46260 | F39: CHIPPER | H39: JORNADA INSTITUCIONAL | I39: ok
A40: 2° | B40: PECO/JUAN | C40: ok | D40: no hubo clases/acto escolar | F40: CHIPPER | G40: COLEGIO | I40: suspendido Ausente peco
A41: 3° | B41: PECO/YAMI | C41: ok | E41: ok | F41: COLEGIO ok
A42: 4º | B42: FRANCO/JUAN | D42: PENDIENTE | E42: 46260 | G42: SUSPENDIDO | J42: 46260
A43: 5º | B43: PECO/JUAN | C43: ok | E43: ok BOX | F43: COLEGIO | I43: ok
A44: 6º | B44: JUAN/YAMI | D44: PENDIENTE | E44: ok BOX | G44: COLEGIO
...
